/apps/python/2.7.11/lib/python2.7/site-packages/matplotlib-1.5.1-py2.7-linux-x86_64.egg/matplotlib/font_manager.py:273: UserWarning: Matplotlib is building the font cache using fc-list. This may take a moment.
  warnings.warn('Matplotlib is building the font cache using fc-list. This may take a moment.')
I tensorflow/stream_executor/dso_loader.cc:135] successfully opened CUDA library libcublas.so.8.0 locally
I tensorflow/stream_executor/dso_loader.cc:135] successfully opened CUDA library libcudnn.so.5 locally
I tensorflow/stream_executor/dso_loader.cc:126] Couldn't open CUDA library libcufft.so.8.0. LD_LIBRARY_PATH: /apps/intel/mkl/2017.2.174/compilers_and_libraries_2017.2.174/linux/mkl/lib/intel64_lin:/apps/intel/mkl/2017.2.174/compilers_and_libraries_2017.2.174/linux/mkl/../compiler/lib/intel64_lin:/apps/intel/mkl/2017.2.174/compilers_and_libraries_2017.2.174/linux/mkl/../compiler/lib/intel64:/apps/python/2.7.13/lib:/apps/intel/fc/16.0.4.258/compiler/lib/intel64:/apps/intel/cc/16.0.4.258/tbb/lib/intel64/gcc4.4:/apps/intel/cc/16.0.4.258/compiler/lib/intel64:/opt/intel/mic/coi/device-linux-release/lib:/opt/intel/mic/myo/lib:/cm/local/apps/cuda-driver/libs/current/lib64:/cm/shared/apps/slurm/16.05.8/lib64
I tensorflow/stream_executor/cuda/cuda_fft.cc:344] Unable to load cuFFT DSO.
I tensorflow/stream_executor/dso_loader.cc:135] successfully opened CUDA library libcuda.so.1 locally
I tensorflow/stream_executor/dso_loader.cc:135] successfully opened CUDA library libcurand.so.8.0 locally
  ___ ___ ___ ___ _____ ___
 |   \_ _/ __|_ _|_   _/ __|
 | |) | | (_ || |  | | \__ \
 |___/___\___|___| |_| |___/ 6.0.0-rc.2

Traceback (most recent call last):
  File "/apps/python/2.7.11/lib/python2.7/runpy.py", line 162, in _run_module_as_main
    "__main__", fname, loader, pkg_name)
  File "/apps/python/2.7.11/lib/python2.7/runpy.py", line 72, in _run_code
    exec code in run_globals
  File "/data/zim021/digits-proj/DIGITS/digits/__main__.py", line 70, in <module>
    main()
  File "/data/zim021/digits-proj/DIGITS/digits/__main__.py", line 55, in main
    import digits.webapp
  File "digits/webapp.py", line 7, in <module>
    from flask.ext.socketio import SocketIO
  File "/data/zim021/digits-env/lib/python2.7/site-packages/flask/exthook.py", line 62, in load_module
    __import__(realname)
  File "/data/zim021/digits-env/lib/python2.7/site-packages/flask_socketio/__init__.py", line 7, in <module>
    from socketio import socketio_manage
  File "/data/zim021/digits-env/lib/python2.7/site-packages/socketio/__init__.py", line 9, in <module>
    from .server import Server
  File "/data/zim021/digits-env/lib/python2.7/site-packages/socketio/server.py", line 1, in <module>
    import logging
KeyboardInterrupt
I tensorflow/stream_executor/dso_loader.cc:135] successfully opened CUDA library libcublas.so.8.0 locally
I tensorflow/stream_executor/dso_loader.cc:135] successfully opened CUDA library libcudnn.so.5 locally
I tensorflow/stream_executor/dso_loader.cc:126] Couldn't open CUDA library libcufft.so.8.0. LD_LIBRARY_PATH: /apps/intel/mkl/2017.2.174/compilers_and_libraries_2017.2.174/linux/mkl/lib/intel64_lin:/apps/intel/mkl/2017.2.174/compilers_and_libraries_2017.2.174/linux/mkl/../compiler/lib/intel64_lin:/apps/intel/mkl/2017.2.174/compilers_and_libraries_2017.2.174/linux/mkl/../compiler/lib/intel64:/apps/python/2.7.13/lib:/apps/intel/fc/16.0.4.258/compiler/lib/intel64:/apps/intel/cc/16.0.4.258/tbb/lib/intel64/gcc4.4:/apps/intel/cc/16.0.4.258/compiler/lib/intel64:/opt/intel/mic/coi/device-linux-release/lib:/opt/intel/mic/myo/lib:/cm/local/apps/cuda-driver/libs/current/lib64:/cm/shared/apps/slurm/16.05.8/lib64
I tensorflow/stream_executor/cuda/cuda_fft.cc:344] Unable to load cuFFT DSO.
I tensorflow/stream_executor/dso_loader.cc:135] successfully opened CUDA library libcuda.so.1 locally
I tensorflow/stream_executor/dso_loader.cc:135] successfully opened CUDA library libcurand.so.8.0 locally
  ___ ___ ___ ___ _____ ___
 |   \_ _/ __|_ _|_   _/ __|
 | |) | | (_ || |  | | \__ \
 |___/___\___|___| |_| |___/ 6.0.0-rc.2

2017-09-27 10:15:52 [INFO ] Loaded 21 jobs.
2017-09-27 10:15:52 [WARNING] Failed to load 4 jobs.
2017-09-27 10:15:52 [DEBUG] 20170123-150155-8b6f - IOError: [Errno 2] No such file or directory: '/data/zim021/digits/jobs/20170123-150155-8b6f/status.pickle'
2017-09-27 10:15:52 [DEBUG] 20170124-101003-28c0 - IOError: [Errno 2] No such file or directory: '/data/zim021/digits/jobs/20170124-101003-28c0/status.pickle'
2017-09-27 10:15:52 [DEBUG] 20170426-095850-3cb3 - IOError: [Errno 2] No such file or directory: '/data/zim021/digits/jobs/20170426-095850-3cb3/status.pickle'
2017-09-27 10:15:52 [DEBUG] 20170830-105800-adb9 - IOError: [Errno 2] No such file or directory: '/data/zim021/digits/jobs/20170830-105800-adb9/status.pickle'
KeyboardInterrupt
I tensorflow/stream_executor/dso_loader.cc:135] successfully opened CUDA library libcublas.so.8.0 locally
I tensorflow/stream_executor/dso_loader.cc:135] successfully opened CUDA library libcudnn.so.5 locally
I tensorflow/stream_executor/dso_loader.cc:126] Couldn't open CUDA library libcufft.so.8.0. LD_LIBRARY_PATH: /apps/intel/mkl/2017.2.174/compilers_and_libraries_2017.2.174/linux/mkl/lib/intel64_lin:/apps/intel/mkl/2017.2.174/compilers_and_libraries_2017.2.174/linux/mkl/../compiler/lib/intel64_lin:/apps/intel/mkl/2017.2.174/compilers_and_libraries_2017.2.174/linux/mkl/../compiler/lib/intel64:/apps/python/2.7.13/lib:/apps/intel/fc/16.0.4.258/compiler/lib/intel64:/apps/intel/cc/16.0.4.258/tbb/lib/intel64/gcc4.4:/apps/intel/cc/16.0.4.258/compiler/lib/intel64:/opt/intel/mic/coi/device-linux-release/lib:/opt/intel/mic/myo/lib:/cm/local/apps/cuda-driver/libs/current/lib64:/cm/shared/apps/slurm/16.05.8/lib64
I tensorflow/stream_executor/cuda/cuda_fft.cc:344] Unable to load cuFFT DSO.
I tensorflow/stream_executor/dso_loader.cc:135] successfully opened CUDA library libcuda.so.1 locally
I tensorflow/stream_executor/dso_loader.cc:135] successfully opened CUDA library libcurand.so.8.0 locally
  ___ ___ ___ ___ _____ ___
 |   \_ _/ __|_ _|_   _/ __|
 | |) | | (_ || |  | | \__ \
 |___/___\___|___| |_| |___/ 6.0.0-rc.2

2017-09-27 10:17:37 [INFO ] Loaded 21 jobs.
2017-09-27 10:17:37 [WARNING] Failed to load 4 jobs.
2017-09-27 10:17:37 [DEBUG] 20170123-150155-8b6f - IOError: [Errno 2] No such file or directory: '/data/zim021/digits/jobs/20170123-150155-8b6f/status.pickle'
2017-09-27 10:17:37 [DEBUG] 20170124-101003-28c0 - IOError: [Errno 2] No such file or directory: '/data/zim021/digits/jobs/20170124-101003-28c0/status.pickle'
2017-09-27 10:17:37 [DEBUG] 20170426-095850-3cb3 - IOError: [Errno 2] No such file or directory: '/data/zim021/digits/jobs/20170426-095850-3cb3/status.pickle'
2017-09-27 10:17:37 [DEBUG] 20170830-105800-adb9 - IOError: [Errno 2] No such file or directory: '/data/zim021/digits/jobs/20170830-105800-adb9/status.pickle'
KeyboardInterrupt
KeyboardInterrupt
Traceback (most recent call last):
  File "/apps/python/2.7.11/lib/python2.7/runpy.py", line 162, in _run_module_as_main
    "__main__", fname, loader, pkg_name)
  File "/apps/python/2.7.11/lib/python2.7/runpy.py", line 72, in _run_code
    exec code in run_globals
  File "/data/zim021/digits-proj/DIGITS/digits/__main__.py", line 70, in <module>
    main()
  File "/data/zim021/digits-proj/DIGITS/digits/__main__.py", line 66, in main
    digits.webapp.scheduler.stop()
  File "digits/scheduler.py", line 352, in stop
    time.sleep(0.1)
  File "/data/zim021/digits-env/lib/python2.7/site-packages/gevent/hub.py", line 194, in sleep
    hub.wait(loop.timer(seconds, ref=ref))
  File "/data/zim021/digits-env/lib/python2.7/site-packages/gevent/hub.py", line 627, in wait
    result = waiter.get()
  File "/data/zim021/digits-env/lib/python2.7/site-packages/gevent/hub.py", line 875, in get
    return self.hub.switch()
  File "/data/zim021/digits-env/lib/python2.7/site-packages/gevent/hub.py", line 606, in switch
    return greenlet.switch(self)
KeyboardInterrupt
